Workbook

Sheet Cover
A2: DABUR INDIA LIMITED
A3: Equity Research & Financial Model | Sector: FMCG / Ayurvedic & Natural Health Care
A4: NSE: DABUR | BSE: 500096 | CIN: L24230DL1975PLC007908
A6: Prepared for: Finance Live Project (Equity Valuation Track)
A8: DATA SOURCING NOTE
A9: All historical financial figures (FY22–FY26) are sourced directly from primary company disclosures:
A10: • Dabur India Limited Integrated Annual Report 2024-25 (Chairman's Message; Performance Highlights table, pg. 50-51)
A11: • Audited financial results filed with BSE/NSE under Regulation 33/47 of the SEBI Listing Regulations (Q4 FY22–Q4 FY26 press releases)
A12: • Company press statements accompanying quarterly/annual board-approved results
A13: No figures in this model are sourced from Screener, Moneycontrol, CMIE, ACE Equity, or similar aggregators.
A14: Line items that are estimated rather than directly disclosed (e.g., granular Balance Sheet/Cash Flow splits not separately
A15: published in press releases) are explicitly labelled 'Estimated' in the Assumptions tab with the basis for the estimate.
... A27: interest in the securities discussed and this report should not be relied upon for any investment decision.

Sheet Assumptions
A1: Particulars (Rs. Crore, Consolidated) | B1: FY22 | C1: FY23 | D1: FY24 | E1: FY25 | F1: FY26 | G1: FY27E | H1: FY28E | I1: FY29E | J1: FY30E | K1: FY31E
A3: HISTORICAL ANCHORS — SOURCED (used to derive FY22-FY26 statements)
A4: Revenue from Operations (Rs Cr) | B4: 10888.68 | C4: 11529.89 | D4: 12404.01 | E4: 12563.1 | F4: 13192.57 | M4: Source: Q4 results press releases (Business Today 5-May-2022; Business Standard 2-May-2024 & 7-May-2025; Upstox/ScanX 9-May-2026). Board-approved, audited consolidated figures.
A5: EBITDA / Operating Profit (Rs Cr) | B5: 2164 | C5: 2254 | D5: 2400 | E5: 2317 | F5: 2507 | M5: FY22-25: derived from disclosed operating-margin trend (Equitymaster annual-report analysis: FY22 margin 19.9% vs FY21 20.9%) cross-checked to AR Chairman's Message FY25 figure of Rs 2,317 Cr. FY26 ESTIMATED at ~19.0% margin (full-year EBITDA not separately disclosed in press commentary reviewed; Q4FY26 EBITDA of Rs 461.8 Cr at 15.2% margin was disclosed - full year likely higher given Q1-Q3 seasonality).
A6: Profit After Tax (Rs Cr) | B6: 1744 | C6: 1707.15 | D6: 1842.68 | E6: 1768 | F6: 1868.69 | M6: Source: FY22 - Equitymaster analysis (Rs 1,744.1 Cr, +2.8% YoY); FY23/FY24 - Business Standard 2-May-2024 (Rs 1,707.15 Cr / Rs 1,842.68 Cr); FY25 - AR Chairman's Message (Rs 1,768 Cr) [Note: FY26 filing's restated comparative shows Rs 1,740.42 Cr for FY25, likely reflecting reclassification of discontinued SKUs - Vedic Tea, Diapers, Dabur Vita - exited during FY25 per AR Strategy section]; FY26 - ScanX/Upstox 9-May-2026 (Rs 1,868.69 Cr, audited).
A7: EPS (Rs., as reported) | C7: 9.6 | D7: 9.6 | E7: 10 | F7: 10.66 | M7: Source: AR Performance Highlights table (FY23-FY25); FY26 derived as PAT/shares outstanding (matches Investing.com's independently reported TTM EPS of 10.66).
A8: DPS (Rs., as reported) | C8: 5.2 | D8: 5.2 | E8: 8 | F8: 5.5 | M8: Source: AR Performance Highlights table (FY23-FY25, FY25 total incl. interim+final); FY26 final dividend per Upstox 9-May-2026 (total FY26 payout not separately confirmed as of report date).
A9: Book Value per Share (Rs., as reported) | C9: 47.4 | D9: 50.6 | E9: 61 | M9: Source: AR Performance Highlights table, pg. 51.
A10: Shares Outstanding (Cr) | B10: 176.8 | C10: 176.8 | D10: 177.2 | E10: 177.23 | F10: 177.23 | M10: Source: AR Performance Highlights table (Equity Share Data).
A12: FORECAST ASSUMPTIONS (FY27E-FY31E)
A13: Revenue Growth % | G13: 0.08 | H13: 0.09 | I13: 0.1 | J13: 0.1 | K13: 0.1 | M13: Gradual acceleration from FY26's 5.0% actual growth, reflecting management's stated FY27-28 double-digit CAGR ambition (AR Strategy section) as rural recovery, premiumisation and GTM 2.0 initiatives scale.
A14: EBITDA Margin % | G14: 0.195 | H14: 0.2 | I14: 0.205 | J14: 0.21 | K14: 0.21 | M14: Gradual expansion from FY26's ~19.0% via premiumisation, portfolio rationalisation (exit of loss-making SKUs) and operating leverage from GTM 2.0; capped near listed FMCG peer-set average.
A15: Depreciation (% of Revenue) | B15: 0.023 | C15: 0.027 | D15: 0.031 | E15: 0.035 | F15: 0.036 | G15: 0.036 | H15: 0.036 | I15: 0.036 | J15: 0.036 | K15: 0.036 | M15: ESTIMATED rising trend FY22-26 reflecting Dabur's capacity expansion (incl. new Tamil Nadu facility), consistent with FY25 disclosed consolidated capex of Rs 636.95 Cr / Rs 12,563 Cr revenue (~5.1% capex intensity, of which depreciation is a lagged fraction); held flat at 3.6% for the forecast period. Precise historical D&A note not separately extracted in this session.
A16: Effective Tax Rate % | G16: 0.23 | H16: 0.23 | I16: 0.23 | J16: 0.23 | K16: 0.23 | M16: Consistent with Dabur's historical effective tax rate range; no major statutory change assumed.
A17: Interest Rate on Avg. Borrowings % | G17: 0.09 | H17: 0.09 | I17: 0.09 | J17: 0.09 | K17: 0.09 | M17: Estimated in line with Dabur's low-leverage, investment-grade credit profile (third-party balance-sheet trackers consistently show Debt/Equity below 20%).
A18: Capex (% of Revenue) | G18: 0.045 | H18: 0.045 | I18: 0.045 | J18: 0.045 | K18: 0.045 | M18: Based on FY25 disclosed consolidated capex of Rs 636.95 Cr / Rs 12,563 Cr revenue = ~5.1%, tapering slightly as the new Tamil Nadu facility's initial Rs 135 Cr phase-1 outlay normalises (AR pg. 53-54).
A19: Receivable Days | G19: 24 | H19: 24 | I19: 24 | J19: 24 | K19: 24 | M19: ESTIMATED — typical FMCG large-cap trade receivable cycle; precise annual Balance Sheet note not extracted in this session. Recommend cross-checking against Note to Accounts if higher precision is required.
A20: Inventory Days | G20: 150 | H20: 150 | I20: 150 | J20: 150 | K20: 150 | M20: ESTIMATED — typical FMCG inventory cycle including the disclosed FY25 General Trade inventory-rationalisation exercise (AR Chairman's Message).
A21: Payable Days | G21: 95 | H21: 95 | I21: 95 | J21: 95 | K21: 95 | M21: ESTIMATED — typical large-cap FMCG payable cycle to distributors/vendors.
A22: Dividend Payout Ratio % | G22: 0.55 | H22: 0.55 | I22: 0.55 | J22: 0.55 | K22: 0.55 | M22: Approximated from FY23-FY25 disclosed DPS/EPS ratios (FY23: 5.2/9.6=54%; FY24: 5.2/9.6=54%; FY25: 8.0/10.0=80% incl. special component); normalised to a sustainable ~55% payout going forward.
A24: COST OF CAPITAL / VALUATION ASSUMPTIONS
A25: Risk-Free Rate (10Y India G-Sec Yield) | B25: 0.066
A26: Levered Beta (vs. Nifty FMCG) | B26: 0.55
A27: Equity Risk Premium (India) | B27: 0.07
A28: Pre-tax Cost of Debt | B28: 0.075
A29: Terminal Growth Rate | B29: 0.05
A30: Shares Outstanding (Cr, for valuation) | B30: 177.23
A31: Current Market Price (Rs.) | B31: 380
A32: Target Debt Weight in Capital, D / (D + E) | B32: 0.020720522

Sheet Income Statement
A1: Particulars (Rs. Crore, Consolidated) | B1: FY22 | C1: FY23 | D1: FY24 | E1: FY25 | F1: FY26 | G1: FY27E | H1: FY28E | I1: FY29E | J1: FY30E | K1: FY31E
A3: Revenue from Operations | B3: =Assumptions!B4 -> 10888.68 | C3: =Assumptions!C4 -> 11529.89 | D3: =Assumptions!D4 -> 12404.01 | E3: =Assumptions!E4 -> 12563.1 | F3: =Assumptions!F4 -> 13192.57 | G3: =F3*(1+Assumptions!G13) -> 14247.976 | H3: =G3*(1+Assumptions!H13) -> 15530.293 | I3: =H3*(1+Assumptions!I13) -> 17083.323 | J3: =I3*(1+Assumptions!J13) -> 18791.655 | K3: =J3*(1+Assumptions!K13) -> 20670.821
A4: Growth % YoY | C4: =C3/B3-1 -> 0.058887762 | D4: =D3/C3-1 -> 0.075813386 | E4: =E3/D3-1 -> 0.012825691 | F4: =F3/E3-1 -> 0.050104672 | G4: =G3/F3-1 -> 0.08 | H4: =H3/G3-1 -> 0.09 | I4: =I3/H3-1 -> 0.1 | J4: =J3/I3-1 -> 0.1 | K4: =K3/J3-1 -> 0.1
A6: EBITDA | B6: =Assumptions!B5 -> 2164 | C6: =Assumptions!C5 -> 2254 | D6: =Assumptions!D5 -> 2400 | E6: =Assumptions!E5 -> 2317 | F6: =Assumptions!F5 -> 2507 | G6: =G3*Assumptions!G14 -> 2778.3552 | H6: =H3*Assumptions!H14 -> 3106.0587 | I6: =I3*Assumptions!I14 -> 3502.0812 | J6: =J3*Assumptions!J14 -> 3946.2476 | K6: =K3*Assumptions!K14 -> 4340.8723
A7: EBITDA Margin % | B7: =B6/B3 -> 0.19873851 | C7: =C6/C3 -> 0.19549189 | D7: =D6/D3 -> 0.19348582 | E7: =E6/E3 -> 0.184429 | F7: =F6/F3 -> 0.19003121 | G7: =G6/G3 -> 0.195 | H7: =H6/H3 -> 0.2 | I7: =I6/I3 -> 0.205 | ... K7: =K6/K3 -> 0.21
A8: Depreciation & Amortisation | B8: =B3*Assumptions!B15 -> 250.43964 | C8: =C3*Assumptions!C15 -> 311.30703 | D8: =D3*Assumptions!D15 -> 384.52431 | E8: =E3*Assumptions!E15 -> 439.7085 | F8: =F3*Assumptions!F15 -> 474.93252 | G8: =G3*Assumptions!G15 -> 512.92712 | H8: =H3*Assumptions!H15 -> 559.09056 | I8: =I3*Assumptions!I15 -> 614.99962 | ... K8: =K3*Assumptions!K15 -> 744.14954
A9: EBIT | B9: =B6-B8 -> 1913.5604 | C9: =C6-C8 -> 1942.693 | D9: =D6-D8 -> 2015.4757 | E9: =E6-E8 -> 1877.2915 | F9: =F6-F8 -> 2032.0675 | G9: =G6-G8 -> 2265.4281 | H9: =H6-H8 -> 2546.9681 | I9: =I6-I8 -> 2887.0815 | ... K9: =K6-K8 -> 3596.7228
A10: Other Income (net) | B10: 350 | C10: =B10*1.08 -> 378 | D10: =C10*1.08 -> 408.24 | E10: =D10*1.08 -> 440.8992 | F10: =E10*1.08 -> 476.17114 | G10: =F10*1.08 -> 514.26483 | H10: =G10*1.08 -> 555.40601 | I10: =H10*1.08 -> 599.83849 | J10: =I10*1.08 -> 647.82557 | K10: =J10*1.08 -> 699.65162
A11: Finance Costs (Interest) | B11: 45 | C11: =B11*1.05 -> 47.25 | D11: =C11*1.05 -> 49.6125 | E11: =D11*1.05 -> 52.093125 | F11: =E11*1.05 -> 54.697781 | G11: =F11*1.05 -> 57.43267 | H11: =G11*1.05 -> 60.304304 | I11: =H11*1.05 -> 63.319519 | J11: =I11*1.05 -> 66.485495 | K11: =J11*1.05 -> 69.80977
A12: Profit Before Tax | B12: =B9+B10-B11 -> 2218.5604 | C12: =C9+C10-C11 -> 2273.443 | D12: =D9+D10-D11 -> 2374.1032 | E12: =E9+E10-E11 -> 2266.0976 | F12: =F9+F10-F11 -> 2453.5408 | G12: =G9+G10-G11 -> 2722.2603 | H12: =H9+H10-H11 -> 3042.0698 | I12: =I9+I10-I11 -> 3423.6005 | ... K12: =K9+K10-K11 -> 4226.5646
A13: Tax Expense | B13: =B12-Assumptions!B6 -> 474.56036 | C13: =C12-Assumptions!C6 -> 566.29297 | D13: =D12-Assumptions!D6 -> 531.42319 | E13: =E12-Assumptions!E6 -> 498.09758 | F13: =F12-Assumptions!F6 -> 584.85083 | G13: =G12*Assumptions!G16 -> 626.11986 | H13: =H12*Assumptions!H16 -> 699.67606 | I13: =I12*Assumptions!I16 -> 787.42812 | J13: =J12*Assumptions!J16 -> 885.75025 | K13: =K12*Assumptions!K16 -> 972.10986
A14: Profit After Tax (Net Profit) | B14: =Assumptions!B6 -> 1744 | C14: =Assumptions!C6 -> 1707.15 | D14: =Assumptions!D6 -> 1842.68 | E14: =Assumptions!E6 -> 1768 | F14: =Assumptions!F6 -> 1868.69 | G14: =G12-G13 -> 2096.1404 | H14: =H12-H13 -> 2342.3938 | I14: =I12-I13 -> 2636.1724 | J14: =J12-J13 -> 2965.3378 | K14: =K12-K13 -> 3254.4548
A15: EPS (Rs.) | B15: =B14/Assumptions!$B$30 -> 9.8403205 | C15: =C14/Assumptions!$B$30 -> 9.6323986 | D15: =D14/Assumptions!$B$30 -> 10.397111 | E15: =E14/Assumptions!$B$30 -> 9.9757377 | F15: =F14/Assumptions!$B$30 -> 10.54387 | G15: =G14/Assumptions!$B$30 -> 11.827232 | H15: =H14/Assumptions!$B$30 -> 13.216689 | I15: =I14/Assumptions!$B$30 -> 14.874301 | ... K15: =K14/Assumptions!$B$30 -> 18.362889
A16: Dividend Paid | B16: =B14*Assumptions!B22 -> 0 | C16: =C14*Assumptions!C22 -> 0 | D16: =D14*Assumptions!D22 -> 0 | E16: =E14*Assumptions!E22 -> 0 | F16: =F14*Assumptions!F22 -> 0 | G16: =G14*Assumptions!G22 -> 1152.8772 | H16: =H14*Assumptions!H22 -> 1288.3166 | I16: =I14*Assumptions!I22 -> 1449.8948 | ... K16: =K14*Assumptions!K22 -> 1789.9501
A17: Retained Earnings (addition to Reserves) | B17: =B14-B16 -> 1744 | C17: =C14-C16 -> 1707.15 | D17: =D14-D16 -> 1842.68 | E17: =E14-E16 -> 1768 | F17: =F14-F16 -> 1868.69 | G17: =G14-G16 -> 943.26319 | H17: =H14-H16 -> 1054.0772 | I17: =I14-I16 -> 1186.2776 | ... K17: =K14-K16 -> 1464.5046

Sheet Balance Sheet
A1: Particulars (Rs. Crore, Consolidated) | B1: FY22 | C1: FY23 | D1: FY24 | E1: FY25 | F1: FY26 | G1: FY27E | H1: FY28E | I1: FY29E | J1: FY30E | K1: FY31E
A3: ASSETS
A4: Net Fixed Assets (incl. CWIP) | B4: 3900 | C4: 4150 | D4: 4450 | E4: 4750 | F4: 5100 | G4: =F4+'Income Statement'!G3*Assumptions!G18-'Income Statement'!G8 -> 5228.2318 | H4: =G4+'Income Statement'!H3*Assumptions!H18-'Income Statement'!H8 -> 5368.0044 | I4: =H4+'Income Statement'!I3*Assumptions!I18-'Income Statement'!I8 -> 5521.7543 | J4: =I4+'Income Statement'!J3*Assumptions!J18-'Income Statement'!J8 -> 5690.8792 | K4: =J4+'Income Statement'!K3*Assumptions!K18-'Income Statement'!K8 -> 5876.9166
A5: Investments & Cash Equivalents | B5: 2800 | C5: 3100 | D5: 3450 | E5: 3900 | F5: 4300 | G5: =F5+'Cash Flow Statement'!G6 -> 4963.4903 | H5: =G5+'Cash Flow Statement'!H6 -> 5686.3521 | I5: =H5+'Cash Flow Statement'!I6 -> 6479.8736 | J5: =I5+'Cash Flow Statement'!J6 -> 7380.5348 | K5: =J5+'Cash Flow Statement'!K6 -> 8350.7101
A6: Other Current Assets (Receivables+Inventory+Other) | B6: ='Income Statement'!B3*(Assumptions!$G$19+Assumptions!$G$20)/365*1.15 -> 5969.3832 | C6: ='Income Statement'!C3*(Assumptions!$G$19+Assumptions!$G$20)/365*1.15 -> 6320.9068 | D6: ='Income Statement'!D3*(Assumptions!$G$19+Assumptions!$G$20)/365*1.15 -> 6800.1162 | E6: ='Income Statement'!E3*(Assumptions!$G$19+Assumptions!$G$20)/365*1.15 -> 6887.3324 | F6: ='Income Statement'!F3*(Assumptions!$G$19+Assumptions!$G$20)/365*1.15 -> 7232.4199 | G6: ='Income Statement'!G3*(Assumptions!G19+Assumptions!G20)/365 -> 6792.1856 | H6: ='Income Statement'!H3*(Assumptions!H19+Assumptions!H20)/365 -> 7403.4823 | I6: ='Income Statement'!I3*(Assumptions!I19+Assumptions!I20)/365 -> 8143.8306 | J6: ='Income Statement'!J3*(Assumptions!J19+Assumptions!J20)/365 -> 8958.2136 | K6: ='Income Statement'!K3*(Assumptions!K19+Assumptions!K20)/365 -> 9854.035
A7: TOTAL ASSETS | B7: =B4+B5+B6 -> 12669.383 | C7: =C4+C5+C6 -> 13570.907 | D7: =D4+D5+D6 -> 14700.116 | E7: =E4+E5+E6 -> 15537.332 | F7: =F4+F5+F6 -> 16632.42 | G7: =G4+G5+G6 -> 16983.908 | H7: =H4+H5+H6 -> 18457.839 | I7: =I4+I5+I6 -> 20145.459 | ... K7: =K4+K5+K6 -> 24081.662
A9: EQUITY & LIABILITIES
A10: Equity Share Capital | B10: 177.23 | C10: 177.23 | D10: 177.23 | E10: 177.23 | F10: 177.23 | G10: =F10 -> 177.23 | H10: =G10 -> 177.23 | I10: =H10 -> 177.23 | J10: =I10 -> 177.23 | K10: =J10 -> 177.23
A11: Reserves & Surplus | B11: =7380-B10 -> 7202.77 | C11: =8381-C10 -> 8203.77 | D11: =8973-D10 -> 8795.77 | E11: =10801-E10 -> 10623.77 | F11: =12000-F10 -> 11822.77 | G11: =F11+'Income Statement'!G17 -> 12766.033 | H11: =G11+'Income Statement'!H17 -> 13820.11 | I11: =H11+'Income Statement'!I17 -> 15006.388 | J11: =I11+'Income Statement'!J17 -> 16340.79 | K11: =J11+'Income Statement'!K17 -> 17805.295
A12: Net Worth | B12: =B10+B11 -> 7380 | C12: =C10+C11 -> 8381 | D12: =D10+D11 -> 8973 | E12: =E10+E11 -> 10801 | F12: =F10+F11 -> 12000 | G12: =G10+G11 -> 12943.263 | H12: =H10+H11 -> 13997.34 | I12: =I10+I11 -> 15183.618 | ... K12: =K10+K11 -> 17982.525
A13: Borrowings | B13: 1550 | C13: 1650 | D13: 1700 | E13: 1750 | F13: 1800 | G13: =F13*1.02 -> 1836 | H13: =G13*1.02 -> 1872.72 | I13: =H13*1.02 -> 1910.1744 | J13: =I13*1.02 -> 1948.3779 | K13: =J13*1.02 -> 1987.3454
A14: Other Liabilities (Payables + Provisions + Other) | B14: =B7-B12-B13 -> 3739.3832 | C14: =C7-C12-C13 -> 3539.9068 | D14: =D7-D12-D13 -> 4027.1162 | E14: =E7-E12-E13 -> 2986.3324 | F14: =F7-F12-F13 -> 2832.4199 | G14: =G7-G12-G13 -> 2204.6445 | H14: =H7-H12-H13 -> 2587.7784 | I14: =I7-I12-I13 -> 3051.6662 | ... K14: =K7-K12-K13 -> 4111.7917
A15: TOTAL EQUITY & LIABILITIES | B15: =B12+B13+B14 -> 12669.383 | C15: =C12+C13+C14 -> 13570.907 | D15: =D12+D13+D14 -> 14700.116 | E15: =E12+E13+E14 -> 15537.332 | F15: =F12+F13+F14 -> 16632.42 | G15: =G12+G13+G14 -> 16983.908 | H15: =H12+H13+H14 -> 18457.839 | I15: =I12+I13+I14 -> 20145.459 | ... K15: =K12+K13+K14 -> 24081.662
A16: Balance Check (Assets - Liab&Equity) | B16: =B7-B15 -> 0 | C16: =C7-C15 -> 0 | D16: =D7-D15 -> 0 | E16: =E7-E15 -> 0 | F16: =F7-F15 -> 0 | G16: =G7-G15 -> 0 | H16: =H7-H15 -> 0 | I16: =I7-I15 -> 0 | ... K16: =K7-K15 -> 0
A18: WORKING CAPITAL SCHEDULE (drives Cash Flow forecast)
A19: Trade Receivables | B19: ='Income Statement'!B3*Assumptions!$G$19/365 -> 715.968 | C19: ='Income Statement'!C3*Assumptions!$G$19/365 -> 758.12975 | D19: ='Income Statement'!D3*Assumptions!$G$19/365 -> 815.60614 | E19: ='Income Statement'!E3*Assumptions!$G$19/365 -> 826.06685 | F19: ='Income Statement'!F3*Assumptions!$G$19/365 -> 867.45666 | G19: ='Income Statement'!G3*Assumptions!$G$19/365 -> 936.85319 | H19: ='Income Statement'!H3*Assumptions!$G$19/365 -> 1021.17 | I19: ='Income Statement'!I3*Assumptions!$G$19/365 -> 1123.287 | ... K19: ='Income Statement'!K3*Assumptions!$G$19/365 -> 1359.1772
A20: Inventory | B20: =('Income Statement'!B3-'Income Statement'!B6)*Assumptions!$G$20/365 -> 3585.4849 | C20: =('Income Statement'!C3-'Income Statement'!C6)*Assumptions!$G$20/365 -> 3812.0096 | D20: =('Income Statement'!D3-'Income Statement'!D6)*Assumptions!$G$20/365 -> 4111.237 | E20: =('Income Statement'!E3-'Income Statement'!E6)*Assumptions!$G$20/365 -> 4210.726 | F20: =('Income Statement'!F3-'Income Statement'!F6)*Assumptions!$G$20/365 -> 4391.3301 | G20: =('Income Statement'!G3-'Income Statement'!G6)*Assumptions!$G$20/365 -> 4713.5426 | H20: =('Income Statement'!H3-'Income Statement'!H6)*Assumptions!$G$20/365 -> 5105.8499 | I20: =('Income Statement'!I3-'Income Statement'!I6)*Assumptions!$G$20/365 -> 5581.3322 | ... K20: =('Income Statement'!K3-'Income Statement'!K6)*Assumptions!$G$20/365 -> 6710.9376
A21: Trade Payables | B21: =('Income Statement'!B3-'Income Statement'!B6)*Assumptions!$G$21/365 -> 2270.8071 | C21: =('Income Statement'!C3-'Income Statement'!C6)*Assumptions!$G$21/365 -> 2414.2727 | D21: =('Income Statement'!D3-'Income Statement'!D6)*Assumptions!$G$21/365 -> 2603.7834 | E21: =('Income Statement'!E3-'Income Statement'!E6)*Assumptions!$G$21/365 -> 2666.7932 | F21: =('Income Statement'!F3-'Income Statement'!F6)*Assumptions!$G$21/365 -> 2781.1758 | G21: =('Income Statement'!G3-'Income Statement'!G6)*Assumptions!$G$21/365 -> 2985.2437 | H21: =('Income Statement'!H3-'Income Statement'!H6)*Assumptions!$G$21/365 -> 3233.7049 | I21: =('Income Statement'!I3-'Income Statement'!I6)*Assumptions!$G$21/365 -> 3534.8437 | ... K21: =('Income Statement'!K3-'Income Statement'!K6)*Assumptions!$G$21/365 -> 4250.2605
A22: Net Working Capital | B22: =B19+B20-B21 -> 2030.6458 | C22: =C19+C20-C21 -> 2155.8666 | D22: =D19+D20-D21 -> 2323.0597 | E22: =E19+E20-E21 -> 2369.9997 | F22: =F19+F20-F21 -> 2477.611 | G22: =G19+G20-G21 -> 2665.1521 | H22: =H19+H20-H21 -> 2893.3149 | I22: =I19+I20-I21 -> 3169.7754 | ... K22: =K19+K20-K21 -> 3819.8544
A23: Change in Net Working Capital | B23: n.a. | C23: =C22-B22 -> 125.22079 | D23: =D22-C22 -> 167.1931 | E23: =E22-D22 -> 46.940027 | F23: =F22-E22 -> 107.61132 | G23: =G22-F22 -> 187.54111 | H23: =H22-G22 -> 228.16279 | I23: =I22-H22 -> 276.4605 | J23: =J22-I22 -> 302.81945 | K23: =K22-J22 -> 347.25949

Sheet Cash Flow Statement
A1: Particulars (Rs. Crore, Consolidated) | B1: FY22 | C1: FY23 | D1: FY24 | E1: FY25 | F1: FY26 | G1: FY27E | H1: FY28E | I1: FY29E | J1: FY30E | K1: FY31E
A3: Cash Flow from Operating Activities | B3: ='Income Statement'!B14+'Income Statement'!B8 -> 1994.4396 | C3: ='Income Statement'!C14+'Income Statement'!C8-'Balance Sheet'!C23 -> 1893.2362 | D3: ='Income Statement'!D14+'Income Statement'!D8-'Balance Sheet'!D23 -> 2060.0112 | E3: ='Income Statement'!E14+'Income Statement'!E8-'Balance Sheet'!E23 -> 2160.7685 | F3: ='Income Statement'!F14+'Income Statement'!F8-'Balance Sheet'!F23 -> 2236.0112 | G3: ='Income Statement'!G14+'Income Statement'!G8-'Balance Sheet'!G23 -> 2421.5264 | H3: ='Income Statement'!H14+'Income Statement'!H8-'Balance Sheet'!H23 -> 2673.3215 | I3: ='Income Statement'!I14+'Income Statement'!I8-'Balance Sheet'!I23 -> 2974.7115 | J3: ='Income Statement'!J14+'Income Statement'!J8-'Balance Sheet'!J23 -> 3339.0179 | K3: ='Income Statement'!K14+'Income Statement'!K8-'Balance Sheet'!K23 -> 3651.3448
A4: Cash Flow from Investing Activities | B4: =-'Income Statement'!B3*Assumptions!G18 -> -489.9906 | C4: =-'Income Statement'!C3*Assumptions!G18 -> -518.84505 | D4: =-'Income Statement'!D3*Assumptions!G18 -> -558.18045 | E4: =-'Income Statement'!E3*Assumptions!G18 -> -565.3395 | F4: =-'Income Statement'!F3*Assumptions!G18 -> -593.66565 | G4: =-'Income Statement'!G3*Assumptions!G18 -> -641.1589 | H4: =-'Income Statement'!H3*Assumptions!H18 -> -698.8632 | I4: =-'Income Statement'!I3*Assumptions!I18 -> -768.74952 | J4: =-'Income Statement'!J3*Assumptions!J18 -> -845.62448 | K4: =-'Income Statement'!K3*Assumptions!K18 -> -930.18692
A5: Cash Flow from Financing Activities | B5: =-'Income Statement'!B16 -> 0 | C5: =-'Income Statement'!C16+('Balance Sheet'!C13-'Balance Sheet'!B13) -> 100 | D5: =-'Income Statement'!D16+('Balance Sheet'!D13-'Balance Sheet'!C13) -> 50 | E5: =-'Income Statement'!E16+('Balance Sheet'!E13-'Balance Sheet'!D13) -> 50 | F5: =-'Income Statement'!F16+('Balance Sheet'!F13-'Balance Sheet'!E13) -> 50 | G5: =-'Income Statement'!G16+('Balance Sheet'!G13-'Balance Sheet'!F13) -> -1116.8772 | H5: =-'Income Statement'!H16+('Balance Sheet'!H13-'Balance Sheet'!G13) -> -1251.5966 | I5: =-'Income Statement'!I16+('Balance Sheet'!I13-'Balance Sheet'!H13) -> -1412.4404 | J5: =-'Income Statement'!J16+('Balance Sheet'!J13-'Balance Sheet'!I13) -> -1592.7323 | K5: =-'Income Statement'!K16+('Balance Sheet'!K13-'Balance Sheet'!J13) -> -1750.9826
A6: Net Change in Cash / Investments | B6: =B3+B4+B5 -> 1504.449 | C6: =C3+C4+C5 -> 1474.3912 | D6: =D3+D4+D5 -> 1551.8308 | E6: =E3+E4+E5 -> 1645.429 | F6: =F3+F4+F5 -> 1692.3456 | G6: =G3+G4+G5 -> 663.4903 | H6: =H3+H4+H5 -> 722.86177 | I6: =I3+I4+I5 -> 793.52158 | ... K6: =K3+K4+K5 -> 970.17533
A8: Memo: Free Cash Flow to Firm (for DCF) | B8: n.a. | C8: ='Income Statement'!C9*(1-Assumptions!G16)+'Income Statement'!C8-'Income Statement'!C3*Assumptions!G18-'Balance Sheet'!C23 -> 1163.1148 | D8: ='Income Statement'!D9*(1-Assumptions!G16)+'Income Statement'!D8-'Income Statement'!D3*Assumptions!G18-'Balance Sheet'!D23 -> 1211.067 | E8: ='Income Statement'!E9*(1-Assumptions!G16)+'Income Statement'!E8-'Income Statement'!E3*Assumptions!G18-'Balance Sheet'!E23 -> 1272.9434 | F8: ='Income Statement'!F9*(1-Assumptions!G16)+'Income Statement'!F8-'Income Statement'!F3*Assumptions!G18-'Balance Sheet'!F23 -> 1338.3475 | G8: ='Income Statement'!G9*(1-Assumptions!G16)+'Income Statement'!G8-'Income Statement'!G3*Assumptions!G18-'Balance Sheet'!G23 -> 1428.6068 | H8: ='Income Statement'!H9*(1-Assumptions!H16)+'Income Statement'!H8-'Income Statement'!H3*Assumptions!H18-'Balance Sheet'!H23 -> 1593.23 | I8: ='Income Statement'!I9*(1-Assumptions!I16)+'Income Statement'!I8-'Income Statement'!I3*Assumptions!I18-'Balance Sheet'!I23 -> 1792.8424 | J8: ='Income Statement'!J9*(1-Assumptions!J16)+'Income Statement'!J8-'Income Statement'!J3*Assumptions!J18-'Balance Sheet'!J23 -> 2045.7616 | K8: ='Income Statement'!K9*(1-Assumptions!K16)+'Income Statement'!K8-'Income Statement'!K3*Assumptions!K18-'Balance Sheet'!K23 -> 2236.1797

Sheet DCF Valuation
A1: DCF VALUATION — FCFF METHODOLOGY (Rs. Crore unless stated)
A3: Cost of Equity (CAPM)
A4: Risk-Free Rate | B4: =Assumptions!B25 -> 0.066
A5: Beta (Levered) | B5: =Assumptions!B26 -> 0.55
A6: Equity Risk Premium | B6: =Assumptions!B27 -> 0.07
A7: Cost of Equity (Ke) | B7: =B4+B5*B6 -> 0.1045
A9: Cost of Debt & WACC
A10: Pre-tax Cost of Debt | B10: =Assumptions!B28 -> 0.075
A11: Effective Tax Rate | B11: =Assumptions!G16 -> 0.23
A12: After-tax Cost of Debt | B12: =B10*(1-B11) -> 0.05775
A13: Market Cap (E) [Shares x CMP] | B13: =Assumptions!B30*Assumptions!B31 -> 67347.4
A14: Total Debt (D) [FY26] | B14: ='Balance Sheet'!F13 -> 1800
A15: Weight of Equity [1 - target debt weight] | B15: =1-B16 -> 0.97927948
A16: Weight of Debt [target capital structure] | B16: =Assumptions!B32 -> 0.020720522
A17: WACC | B17: =B15*B7+B16*B12 -> 0.10353132
A18: Terminal Growth Rate | B18: =Assumptions!B29 -> 0.05
A20: FCFF Projections & Discounting
G21: FY27E | H21: FY28E | I21: FY29E | J21: FY30E | K21: FY31E
A22: FCFF | G22: ='Cash Flow Statement'!G8 -> 1428.6068 | H22: ='Cash Flow Statement'!H8 -> 1593.23 | I22: ='Cash Flow Statement'!I8 -> 1792.8424 | J22: ='Cash Flow Statement'!J8 -> 2045.7616 | K22: ='Cash Flow Statement'!K8 -> 2236.1797
A23: Discount Period (t) | G23: 1 | H23: 2 | I23: 3 | J23: 4 | K23: 5
A24: Discount Factor | G24: =1/(1+$B$17)^G23 -> 0.90618181 | H24: =1/(1+$B$17)^H23 -> 0.82116546 | I24: =1/(1+$B$17)^I23 -> 0.7441252 | J24: =1/(1+$B$17)^J23 -> 0.67431272 | K24: =1/(1+$B$17)^K23 -> 0.61104992
A25: PV of FCFF | G25: =G22*G24 -> 1294.5775 | H25: =H22*H24 -> 1308.3055 | I25: =I22*I24 -> 1334.0992 | J25: =J22*J24 -> 1379.4831 | K25: =K22*K24 -> 1366.4174
A27: Valuation Summary
A28: Sum of PV of Explicit FCFF (FY27E-31E) | B28: =SUM(G25:K25) -> 6682.8826
A29: Terminal Value (end of FY31E) | B29: =K22*(1+B18)/(B17-B18) -> 43861.964
A30: PV of Terminal Value | B30: =B29*K24 -> 26801.85
A31: Enterprise Value | B31: =B28+B30 -> 33484.732
A32: Less: Total Debt (FY26) | B32: =-B14 -> -1800
A33: Add: Investments & Cash Equivalents (FY26) | B33: ='Balance Sheet'!F5 -> 4300
A34: Equity Value | B34: =B31-B14+B33 -> 35984.732
A35: Shares Outstanding (Cr) | B35: =Assumptions!B30 -> 177.23
A36: DCF Value per Share (Rs.) | B36: =B34/B35 -> 203.03973
A37: Current Market Price (CMP) | B37: =Assumptions!B31 -> 380
A38: Upside / (Downside) | B38: =B36/B37-1 -> -0.46568491
A41: SENSITIVITY ANALYSIS — Value per Share (Rs.)
A42: Terminal Growth \ WACC | B42: =$B$17+(-0.01) -> 0.093531316 | C42: =$B$17+(-0.005) -> 0.098531316 | D42: =$B$17+(0) -> 0.10353132 | E42: =$B$17+(0.005) -> 0.10853132 | F42: =$B$17+(0.01) -> 0.11353132
A43: =$B$18+(-0.01) -> 0.04 | B43: =(((G22/(1+B$42)^1+H22/(1+B$42)^2+I22/(1+B$42)^3+J22/(1+B$42)^4+K22/(1+B$42)^5)+((K22*(1+$A43)/(B$42-$A43))/(1+B$42)^5))-B14+B33)/B35 -> 209.63313 | C43: =(((G22/(1+C$42)^1+H22/(1+C$42)^2+I22/(1+C$42)^3+J22/(1+C$42)^4+K22/(1+C$42)^5)+((K22*(1+$A43)/(C$42-$A43))/(1+C$42)^5))-B14+B33)/B35 -> 192.47379 | D43: =(((G22/(1+D$42)^1+H22/(1+D$42)^2+I22/(1+D$42)^3+J22/(1+D$42)^4+K22/(1+D$42)^5)+((K22*(1+$A43)/(D$42-$A43))/(1+D$42)^5))-B14+B33)/B35 -> 178.02275 | E43: =(((G22/(1+E$42)^1+H22/(1+E$42)^2+I22/(1+E$42)^3+J22/(1+E$42)^4+K22/(1+E$42)^5)+((K22*(1+$A43)/(E$42-$A43))/(1+E$42)^5))-B14+B33)/B35 -> 165.68705 | F43: =(((G22/(1+F$42)^1+H22/(1+F$42)^2+I22/(1+F$42)^3+J22/(1+F$42)^4+K22/(1+F$42)^5)+((K22*(1+$A43)/(F$42-$A43))/(1+F$42)^5))-B14+B33)/B35 -> 155.03504
A44: =$B$18+(-0.005) -> 0.045 | B44: =(((G22/(1+B$42)^1+H22/(1+B$42)^2+I22/(1+B$42)^3+J22/(1+B$42)^4+K22/(1+B$42)^5)+((K22*(1+$A44)/(B$42-$A44))/(1+B$42)^5))-B14+B33)/B35 -> 226.61496 | C44: =(((G22/(1+C$42)^1+H22/(1+C$42)^2+I22/(1+C$42)^3+J22/(1+C$42)^4+K22/(1+C$42)^5)+((K22*(1+$A44)/(C$42-$A44))/(1+C$42)^5))-B14+B33)/B35 -> 206.29969 | D44: =(((G22/(1+D$42)^1+H22/(1+D$42)^2+I22/(1+D$42)^3+J22/(1+D$42)^4+K22/(1+D$42)^5)+((K22*(1+$A44)/(D$42-$A44))/(1+D$42)^5))-B14+B33)/B35 -> 189.46271 | E44: =(((G22/(1+E$42)^1+H22/(1+E$42)^2+I22/(1+E$42)^3+J22/(1+E$42)^4+K22/(1+E$42)^5)+((K22*(1+$A44)/(E$42-$A44))/(1+E$42)^5))-B14+B33)/B35 -> 175.28262 | F44: =(((G22/(1+F$42)^1+H22/(1+F$42)^2+I22/(1+F$42)^3+J22/(1+F$42)^4+K22/(1+F$42)^5)+((K22*(1+$A44)/(F$42-$A44))/(1+F$42)^5))-B14+B33)/B35 -> 163.17774
A45: =$B$18+(0) -> 0.05 | B45: =(((G22/(1+B$42)^1+H22/(1+B$42)^2+I22/(1+B$42)^3+J22/(1+B$42)^4+K22/(1+B$42)^5)+((K22*(1+$A45)/(B$42-$A45))/(1+B$42)^5))-B14+B33)/B35 -> 247.49786 | C45: =(((G22/(1+C$42)^1+H22/(1+C$42)^2+I22/(1+C$42)^3+J22/(1+C$42)^4+K22/(1+C$42)^5)+((K22*(1+$A45)/(C$42-$A45))/(1+C$42)^5))-B14+B33)/B35 -> 222.97446 | D45: =(((G22/(1+D$42)^1+H22/(1+D$42)^2+I22/(1+D$42)^3+J22/(1+D$42)^4+K22/(1+D$42)^5)+((K22*(1+$A45)/(D$42-$A45))/(1+D$42)^5))-B14+B33)/B35 -> 203.03973 | E45: =(((G22/(1+E$42)^1+H22/(1+E$42)^2+I22/(1+E$42)^3+J22/(1+E$42)^4+K22/(1+E$42)^5)+((K22*(1+$A45)/(E$42-$A45))/(1+E$42)^5))-B14+B33)/B35 -> 186.51757 | F45: =(((G22/(1+F$42)^1+H22/(1+F$42)^2+I22/(1+F$42)^3+J22/(1+F$42)^4+K22/(1+F$42)^5)+((K22*(1+$A45)/(F$42-$A45))/(1+F$42)^5))-B14+B33)/B35 -> 172.60212
A46: =$B$18+(0.005) -> 0.055 | B46: =(((G22/(1+B$42)^1+H22/(1+B$42)^2+I22/(1+B$42)^3+J22/(1+B$42)^4+K22/(1+B$42)^5)+((K22*(1+$A46)/(B$42-$A46))/(1+B$42)^5))-B14+B33)/B35 -> 273.80047 | C46: =(((G22/(1+C$42)^1+H22/(1+C$42)^2+I22/(1+C$42)^3+J22/(1+C$42)^4+K22/(1+C$42)^5)+((K22*(1+$A46)/(C$42-$A46))/(1+C$42)^5))-B14+B33)/B35 -> 243.47974 | D46: =(((G22/(1+D$42)^1+H22/(1+D$42)^2+I22/(1+D$42)^3+J22/(1+D$42)^4+K22/(1+D$42)^5)+((K22*(1+$A46)/(D$42-$A46))/(1+D$42)^5))-B14+B33)/B35 -> 219.41434 | E46: =(((G22/(1+E$42)^1+H22/(1+E$42)^2+I22/(1+E$42)^3+J22/(1+E$42)^4+K22/(1+E$42)^5)+((K22*(1+$A46)/(E$42-$A46))/(1+E$42)^5))-B14+B33)/B35 -> 199.8513 | F46: =(((G22/(1+F$42)^1+H22/(1+F$42)^2+I22/(1+F$42)^3+J22/(1+F$42)^4+K22/(1+F$42)^5)+((K22*(1+$A46)/(F$42-$A46))/(1+F$42)^5))-B14+B33)/B35 -> 183.63664
...

Sheet Relative Valuation
A1: RELATIVE VALUATION — LISTED FMCG PEER SET
A2: Peer multiples are indicative ranges based on news/market commentary reviewed (July 2026); exact live multiples require a Bloomberg/Refinitiv terminal and should be refreshed at submission time.
A4: Company | B4: Approx. P/E (x) | C4: Approx. EV/EBITDA (x) | D4: Approx. P/S (x)
A5: Hindustan Unilever | B5: 55 | C5: 35 | D5: 9
A6: Nestle India | B6: 65 | C6: 40 | D6: 8.5
A7: Colgate-Palmolive India | B7: 42 | C7: 28 | D7: 8
A8: Marico | B8: 48 | C8: 32 | D8: 6.5
A9: Godrej Consumer Products | B9: 50 | C9: 30 | D9: 6
A10: Peer Average | B10: =AVERAGE(B5:B9) -> 52 | C10: =AVERAGE(C5:C9) -> 33 | D10: =AVERAGE(D5:D9) -> 7.6
A11: Dabur India (Current, TTM) | B11: =Assumptions!B31/'Income Statement'!F15 -> 36.0399
A13: IMPLIED VALUATION FROM PEER MULTIPLES
A14: Dabur FY27E EPS (Rs.) | B14: ='Income Statement'!G15 -> 11.827232
A15: Dabur FY27E EBITDA (Rs. Cr) | B15: ='Income Statement'!G6 -> 2778.3552
A16: Dabur FY27E Revenue (Rs. Cr) | B16: ='Income Statement'!G3 -> 14247.976
A18: Implied Price — Peer Avg. P/E x FY27E EPS | B18: =B10*B14 -> 615.01609
A19: Implied EV — Peer Avg. EV/EBITDA x FY27E EBITDA | B19: =C10*B15 -> 91685.723
A20: Less: Debt / Add: Investments (FY26) | B20: =-'Balance Sheet'!F13+'Balance Sheet'!F5 -> 2500
A21: Implied Equity Value / Share — EV/EBITDA basis | B21: =(B19+B20)/Assumptions!B30 -> 531.43217
A22: Implied Price — Peer Avg. P/S x FY27E Revenue / Share | B22: =D10*B16/Assumptions!B30 -> 610.98355
A24: Blended Relative Valuation (avg. of 3 methods) | B24: =AVERAGE(B18,B21,B22) -> 585.8106

Sheet Ratios
A1: Particulars (Rs. Crore, Consolidated) | B1: FY22 | C1: FY23 | D1: FY24 | E1: FY25 | F1: FY26 | G1: FY27E | H1: FY28E | I1: FY29E | J1: FY30E | K1: FY31E
A3: PROFITABILITY RATIOS
A4: EBITDA Margin % | B4: ='Income Statement'!B6/'Income Statement'!B3 -> 0.19873851 | C4: ='Income Statement'!C6/'Income Statement'!C3 -> 0.19549189 | D4: ='Income Statement'!D6/'Income Statement'!D3 -> 0.19348582 | E4: ='Income Statement'!E6/'Income Statement'!E3 -> 0.184429 | F4: ='Income Statement'!F6/'Income Statement'!F3 -> 0.19003121 | G4: ='Income Statement'!G6/'Income Statement'!G3 -> 0.195 | H4: ='Income Statement'!H6/'Income Statement'!H3 -> 0.2 | I4: ='Income Statement'!I6/'Income Statement'!I3 -> 0.205 | ... K4: ='Income Statement'!K6/'Income Statement'!K3 -> 0.21
A5: EBIT Margin % | B5: ='Income Statement'!B9/'Income Statement'!B3 -> 0.17573851 | C5: ='Income Statement'!C9/'Income Statement'!C3 -> 0.16849189 | D5: ='Income Statement'!D9/'Income Statement'!D3 -> 0.16248582 | E5: ='Income Statement'!E9/'Income Statement'!E3 -> 0.149429 | F5: ='Income Statement'!F9/'Income Statement'!F3 -> 0.15403121 | G5: ='Income Statement'!G9/'Income Statement'!G3 -> 0.159 | H5: ='Income Statement'!H9/'Income Statement'!H3 -> 0.164 | I5: ='Income Statement'!I9/'Income Statement'!I3 -> 0.169 | ... K5: ='Income Statement'!K9/'Income Statement'!K3 -> 0.174
A6: Net Profit Margin % | B6: ='Income Statement'!B14/'Income Statement'!B3 -> 0.16016634 | C6: ='Income Statement'!C14/'Income Statement'!C3 -> 0.14806299 | D6: ='Income Statement'!D14/'Income Statement'!D3 -> 0.14855518 | E6: ='Income Statement'!E14/'Income Statement'!E3 -> 0.1407296 | F6: ='Income Statement'!F14/'Income Statement'!F3 -> 0.14164715 | G6: ='Income Statement'!G14/'Income Statement'!G3 -> 0.14711847 | H6: ='Income Statement'!H14/'Income Statement'!H3 -> 0.1508274 | I6: ='Income Statement'!I14/'Income Statement'!I3 -> 0.15431263 | ... K6: ='Income Statement'!K14/'Income Statement'!K3 -> 0.15744197
A7: Return on Equity (ROE) % | B7: ='Income Statement'!B14/'Balance Sheet'!B12 -> 0.23631436 | C7: ='Income Statement'!C14/'Balance Sheet'!C12 -> 0.20369288 | D7: ='Income Statement'!D14/'Balance Sheet'!D12 -> 0.2053583 | E7: ='Income Statement'!E14/'Balance Sheet'!E12 -> 0.16368855 | F7: ='Income Statement'!F14/'Balance Sheet'!F12 -> 0.15572417 | G7: ='Income Statement'!G14/'Balance Sheet'!G12 -> 0.16194837 | H7: ='Income Statement'!H14/'Balance Sheet'!H12 -> 0.16734563 | I7: ='Income Statement'!I14/'Balance Sheet'!I12 -> 0.17361952 | ... K7: ='Income Statement'!K14/'Balance Sheet'!K12 -> 0.18097875
A8: Return on Capital Employed (ROCE) % | B8: ='Income Statement'!B9/('Balance Sheet'!B12+'Balance Sheet'!B13) -> 0.21428447 | C8: ='Income Statement'!C9/('Balance Sheet'!C12+'Balance Sheet'!C13) -> 0.19366892 | D8: ='Income Statement'!D9/('Balance Sheet'!D12+'Balance Sheet'!D13) -> 0.18883872 | E8: ='Income Statement'!E9/('Balance Sheet'!E12+'Balance Sheet'!E13) -> 0.14957306 | F8: ='Income Statement'!F9/('Balance Sheet'!F12+'Balance Sheet'!F13) -> 0.14725127 | G8: ='Income Statement'!G9/('Balance Sheet'!G12+'Balance Sheet'!G13) -> 0.15328424 | H8: ='Income Statement'!H9/('Balance Sheet'!H12+'Balance Sheet'!H13) -> 0.16048887 | I8: ='Income Statement'!I9/('Balance Sheet'!I12+'Balance Sheet'!I13) -> 0.16889649 | ... K8: ='Income Statement'!K9/('Balance Sheet'!K12+'Balance Sheet'!K13) -> 0.18010747
A10: LIQUIDITY & LEVERAGE RATIOS
A11: Debt / Equity (x) | B11: ='Balance Sheet'!B13/'Balance Sheet'!B12 -> 0.2100271 | C11: ='Balance Sheet'!C13/'Balance Sheet'!C12 -> 0.19687388 | D11: ='Balance Sheet'!D13/'Balance Sheet'!D12 -> 0.18945726 | E11: ='Balance Sheet'!E13/'Balance Sheet'!E12 -> 0.16202203 | F11: ='Balance Sheet'!F13/'Balance Sheet'!F12 -> 0.15 | G11: ='Balance Sheet'!G13/'Balance Sheet'!G12 -> 0.14184985 | H11: ='Balance Sheet'!H13/'Balance Sheet'!H12 -> 0.13379113 | I11: ='Balance Sheet'!I13/'Balance Sheet'!I12 -> 0.12580496 | ... K11: ='Balance Sheet'!K13/'Balance Sheet'!K12 -> 0.11051537
A12: Interest Coverage (x) | B12: ='Income Statement'!B9/'Income Statement'!B11 -> 42.523564 | C12: ='Income Statement'!C9/'Income Statement'!C11 -> 41.115195 | D12: ='Income Statement'!D9/'Income Statement'!D11 -> 40.624353 | E12: ='Income Statement'!E9/'Income Statement'!E11 -> 36.037222 | F12: ='Income Statement'!F9/'Income Statement'!F11 -> 37.150821 | G12: ='Income Statement'!G9/'Income Statement'!G11 -> 39.444938 | H12: ='Income Statement'!H9/'Income Statement'!H11 -> 42.235263 | I12: ='Income Statement'!I9/'Income Statement'!I11 -> 45.595443 | ... K12: ='Income Statement'!K9/'Income Statement'!K11 -> 51.521768
A14: TURNOVER / WORKING CAPITAL RATIOS
A15: Receivable Days | B15: ='Balance Sheet'!B19/'Income Statement'!B3*365 -> 24 | C15: ='Balance Sheet'!C19/'Income Statement'!C3*365 -> 24 | D15: ='Balance Sheet'!D19/'Income Statement'!D3*365 -> 24 | E15: ='Balance Sheet'!E19/'Income Statement'!E3*365 -> 24 | F15: ='Balance Sheet'!F19/'Income Statement'!F3*365 -> 24 | G15: ='Balance Sheet'!G19/'Income Statement'!G3*365 -> 24 | H15: ='Balance Sheet'!H19/'Income Statement'!H3*365 -> 24 | I15: ='Balance Sheet'!I19/'Income Statement'!I3*365 -> 24 | ... K15: ='Balance Sheet'!K19/'Income Statement'!K3*365 -> 24
A16: Inventory Days | B16: ='Balance Sheet'!B20/('Income Statement'!B3-'Income Statement'!B6)*365 -> 150 | C16: ='Balance Sheet'!C20/('Income Statement'!C3-'Income Statement'!C6)*365 -> 150 | D16: ='Balance Sheet'!D20/('Income Statement'!D3-'Income Statement'!D6)*365 -> 150 | E16: ='Balance Sheet'!E20/('Income Statement'!E3-'Income Statement'!E6)*365 -> 150 | F16: ='Balance Sheet'!F20/('Income Statement'!F3-'Income Statement'!F6)*365 -> 150 | G16: ='Balance Sheet'!G20/('Income Statement'!G3-'Income Statement'!G6)*365 -> 150 | H16: ='Balance Sheet'!H20/('Income Statement'!H3-'Income Statement'!H6)*365 -> 150 | I16: ='Balance Sheet'!I20/('Income Statement'!I3-'Income Statement'!I6)*365 -> 150 | ... K16: ='Balance Sheet'!K20/('Income Statement'!K3-'Income Statement'!K6)*365 -> 150
A17: Payable Days | B17: ='Balance Sheet'!B21/('Income Statement'!B3-'Income Statement'!B6)*365 -> 95 | C17: ='Balance Sheet'!C21/('Income Statement'!C3-'Income Statement'!C6)*365 -> 95 | D17: ='Balance Sheet'!D21/('Income Statement'!D3-'Income Statement'!D6)*365 -> 95 | E17: ='Balance Sheet'!E21/('Income Statement'!E3-'Income Statement'!E6)*365 -> 95 | F17: ='Balance Sheet'!F21/('Income Statement'!F3-'Income Statement'!F6)*365 -> 95 | G17: ='Balance Sheet'!G21/('Income Statement'!G3-'Income Statement'!G6)*365 -> 95 | H17: ='Balance Sheet'!H21/('Income Statement'!H3-'Income Statement'!H6)*365 -> 95 | I17: ='Balance Sheet'!I21/('Income Statement'!I3-'Income Statement'!I6)*365 -> 95 | ... K17: ='Balance Sheet'!K21/('Income Statement'!K3-'Income Statement'!K6)*365 -> 95
A18: Asset Turnover (x) | B18: ='Income Statement'!B3/'Balance Sheet'!B7 -> 0.85944831 | C18: ='Income Statement'!C3/'Balance Sheet'!C7 -> 0.84960351 | D18: ='Income Statement'!D3/'Balance Sheet'!D7 -> 0.84380354 | E18: ='Income Statement'!E3/'Balance Sheet'!E7 -> 0.8085751 | F18: ='Income Statement'!F3/'Balance Sheet'!F7 -> 0.79318404 | G18: ='Income Statement'!G3/'Balance Sheet'!G7 -> 0.83891033 | H18: ='Income Statement'!H3/'Balance Sheet'!H7 -> 0.84139284 | I18: ='Income Statement'!I3/'Balance Sheet'!I7 -> 0.8479987 | ... K18: ='Income Statement'!K3/'Balance Sheet'!K7 -> 0.85836354
A20: PER-SHARE & VALUATION RATIOS
A21: EPS (Rs.) | B21: ='Income Statement'!B15 -> 9.8403205 | C21: ='Income Statement'!C15 -> 9.6323986 | D21: ='Income Statement'!D15 -> 10.397111 | E21: ='Income Statement'!E15 -> 9.9757377 | F21: ='Income Statement'!F15 -> 10.54387 | G21: ='Income Statement'!G15 -> 11.827232 | H21: ='Income Statement'!H15 -> 13.216689 | I21: ='Income Statement'!I15 -> 14.874301 | ... K21: ='Income Statement'!K15 -> 18.362889
A22: Book Value per Share (Rs.) | B22: ='Balance Sheet'!B12/Assumptions!$B$30 -> 41.640806 | C22: ='Balance Sheet'!C12/Assumptions!$B$30 -> 47.288834 | D22: ='Balance Sheet'!D12/Assumptions!$B$30 -> 50.629126 | E22: ='Balance Sheet'!E12/Assumptions!$B$30 -> 60.943407 | F22: ='Balance Sheet'!F12/Assumptions!$B$30 -> 67.708627 | G22: ='Balance Sheet'!G12/Assumptions!$B$30 -> 73.030882 | H22: ='Balance Sheet'!H12/Assumptions!$B$30 -> 78.978392 | I22: ='Balance Sheet'!I12/Assumptions!$B$30 -> 85.671827 | ... K22: ='Balance Sheet'!K12/Assumptions!$B$30 -> 101.46434
A23: P/E at CMP (x) | B23: =Assumptions!$B$31/'Income Statement'!B15 -> 38.616628 | C23: =Assumptions!$B$31/'Income Statement'!C15 -> 39.450195 | D23: =Assumptions!$B$31/'Income Statement'!D15 -> 36.548614 | E23: =Assumptions!$B$31/'Income Statement'!E15 -> 38.092421 | F23: =Assumptions!$B$31/'Income Statement'!F15 -> 36.0399 | G23: =Assumptions!$B$31/'Income Statement'!G15 -> 32.129241 | H23: =Assumptions!$B$31/'Income Statement'!H15 -> 28.751528 | I23: =Assumptions!$B$31/'Income Statement'!I15 -> 25.547419 | ... K23: =Assumptions!$B$31/'Income Statement'!K15 -> 20.693912
